Workbook

Sheet Cover
B2: CONSULTING WALLAH · RESOURCES
B3: Drug & Alternatives Look-up
B4: 227 generics · therapeutic class · common forms · same-class alternatives · brand examples (India / UAE-GCC) · ATC · procurement notes. Version 27 Oct 2026.
B6: HOW TO USE
B7: 1. Open the Lookup sheet. Type part of a generic, brand or class in the yellow search cell (B3); matching rows appear below.
B8: 2. Or use the filter arrows on the Data sheet — filter by Class to see every molecule in a class and its alternatives.
B9: 3. Use the Alternatives column to build tender lots (e.g. "PPI — any of omeprazole / pantoprazole / esomeprazole") and the Notes column for stewardship, cold-chain and controlled-drug flags.
B11: WHAT THIS IS — AND IS NOT
B12: This is a procurement reference compiled by practitioners for formulary rationalisation, tender lot design and benchmarking. It is not clinical guidance. Any substitution must be approved by the Pharmacy & Therapeutics committee / treating clinician, and registration status must be checked with the relevant authority (CDSCO, MOHAP, DoH, DHA, SFDA).
B13: Brand names are examples only and belong to their owners; availability and registration vary by market and over time.
B15: Free to use and share with attribution · consultingwallah.com/resources.html · consultingwallah@gmail.com

Sheet Lookup
B1: Drug & Alternatives Look-up
B2: Type part of a generic, brand or class →
B3: omeprazole | C3: =IF(B3="","Enter a search term",COUNTIF(Data!$I:$I,TRUE())&" match(es)") -> 4 match(es)
B5: Generic | C5: Therapeutic class | D5: Common forms & strengths | E5: Alternatives (same class / therapeutic) | F5: Brand examples — India | G5: Brand examples — UAE / GCC | H5: ATC | I5: Procurement note
B6: =IFERROR(INDEX(Data!$A$2:$A$228,MATCH(1,Data!$J$2:$J$228,0)),"") -> Esomeprazole | C6: =IFERROR(INDEX(Data!$B$2:$B$228,MATCH(1,Data!$J$2:$J$228,0)),"") -> Proton pump inhibitor | D6: =IFERROR(INDEX(Data!$C$2:$C$228,MATCH(1,Data!$J$2:$J$228,0)),"") -> 20/40 mg tab; 40 mg inj | E6: =IFERROR(INDEX(Data!$D$2:$D$228,MATCH(1,Data!$J$2:$J$228,0)),"") -> Pantoprazole; Omeprazole; Rabeprazole | F6: =IFERROR(INDEX(Data!$E$2:$E$228,MATCH(1,Data!$J$2:$J$228,0)),"") -> Nexpro, Esoz | G6: =IFERROR(INDEX(Data!$F$2:$F$228,MATCH(1,Data!$J$2:$J$228,0)),"") -> Nexium, Esomax | H6: =IFERROR(INDEX(Data!$G$2:$G$228,MATCH(1,Data!$J$2:$J$228,0)),"") -> A02BC05 | I6: =IFERROR(INDEX(Data!$H$2:$H$228,MATCH(1,Data!$J$2:$J$228,0)),"") -> 0
B7: =IFERROR(INDEX(Data!$A$2:$A$228,MATCH(2,Data!$J$2:$J$228,0)),"") -> Omeprazole | C7: =IFERROR(INDEX(Data!$B$2:$B$228,MATCH(2,Data!$J$2:$J$228,0)),"") -> Proton pump inhibitor | D7: =IFERROR(INDEX(Data!$C$2:$C$228,MATCH(2,Data!$J$2:$J$228,0)),"") -> 20/40 mg cap; 40 mg inj | E7: =IFERROR(INDEX(Data!$D$2:$D$228,MATCH(2,Data!$J$2:$J$228,0)),"") -> Pantoprazole; Esomeprazole; Rabeprazole | F7: =IFERROR(INDEX(Data!$E$2:$E$228,MATCH(2,Data!$J$2:$J$228,0)),"") -> Omez, Ocid | G7: =IFERROR(INDEX(Data!$F$2:$F$228,MATCH(2,Data!$J$2:$J$228,0)),"") -> Losec, Risek | H7: =IFERROR(INDEX(Data!$G$2:$G$228,MATCH(2,Data!$J$2:$J$228,0)),"") -> A02BC01 | I7: =IFERROR(INDEX(Data!$H$2:$H$228,MATCH(2,Data!$J$2:$J$228,0)),"") -> PPIs are interchangeable at class level for most formularies — single-brand tendering saves 20–40%.
B8: =IFERROR(INDEX(Data!$A$2:$A$228,MATCH(3,Data!$J$2:$J$228,0)),"") -> Pantoprazole | C8: =IFERROR(INDEX(Data!$B$2:$B$228,MATCH(3,Data!$J$2:$J$228,0)),"") -> Proton pump inhibitor | D8: =IFERROR(INDEX(Data!$C$2:$C$228,MATCH(3,Data!$J$2:$J$228,0)),"") -> 40 mg tab; 40 mg inj | E8: =IFERROR(INDEX(Data!$D$2:$D$228,MATCH(3,Data!$J$2:$J$228,0)),"") -> Omeprazole; Esomeprazole; Rabeprazole | F8: =IFERROR(INDEX(Data!$E$2:$E$228,MATCH(3,Data!$J$2:$J$228,0)),"") -> Pan, Pantocid | G8: =IFERROR(INDEX(Data!$F$2:$F$228,MATCH(3,Data!$J$2:$J$228,0)),"") -> Controloc, Pantozol | H8: =IFERROR(INDEX(Data!$G$2:$G$228,MATCH(3,Data!$J$2:$J$228,0)),"") -> A02BC02 | I8: =IFERROR(INDEX(Data!$H$2:$H$228,MATCH(3,Data!$J$2:$J$228,0)),"") -> IV pantoprazole is a common over-use item — review IV→oral switch.
B9: =IFERROR(INDEX(Data!$A$2:$A$228,MATCH(4,Data!$J$2:$J$228,0)),"") -> Rabeprazole | C9: =IFERROR(INDEX(Data!$B$2:$B$228,MATCH(4,Data!$J$2:$J$228,0)),"") -> Proton pump inhibitor | D9: =IFERROR(INDEX(Data!$C$2:$C$228,MATCH(4,Data!$J$2:$J$228,0)),"") -> 20 mg tab | E9: =IFERROR(INDEX(Data!$D$2:$D$228,MATCH(4,Data!$J$2:$J$228,0)),"") -> Pantoprazole; Omeprazole; Esomeprazole | F9: =IFERROR(INDEX(Data!$E$2:$E$228,MATCH(4,Data!$J$2:$J$228,0)),"") -> Razo, Rabicip | G9: =IFERROR(INDEX(Data!$F$2:$F$228,MATCH(4,Data!$J$2:$J$228,0)),"") -> Pariet, Rabezol | H9: =IFERROR(INDEX(Data!$G$2:$G$228,MATCH(4,Data!$J$2:$J$228,0)),"") -> A02BC04 | I9: =IFERROR(INDEX(Data!$H$2:$H$228,MATCH(4,Data!$J$2:$J$228,0)),"") -> 0
B10: =IFERROR(INDEX(Data!$A$2:$A$228,MATCH(5,Data!$J$2:$J$228,0)),"") | C10: =IFERROR(INDEX(Data!$B$2:$B$228,MATCH(5,Data!$J$2:$J$228,0)),"") | D10: =IFERROR(INDEX(Data!$C$2:$C$228,MATCH(5,Data!$J$2:$J$228,0)),"") | E10: =IFERROR(INDEX(Data!$D$2:$D$228,MATCH(5,Data!$J$2:$J$228,0)),"") | F10: =IFERROR(INDEX(Data!$E$2:$E$228,MATCH(5,Data!$J$2:$J$228,0)),"") | G10: =IFERROR(INDEX(Data!$F$2:$F$228,MATCH(5,Data!$J$2:$J$228,0)),"") | H10: =IFERROR(INDEX(Data!$G$2:$G$228,MATCH(5,Data!$J$2:$J$228,0)),"") | I10: =IFERROR(INDEX(Data!$H$2:$H$228,MATCH(5,Data!$J$2:$J$228,0)),"")
B11: =IFERROR(INDEX(Data!$A$2:$A$228,MATCH(6,Data!$J$2:$J$228,0)),"") | C11: =IFERROR(INDEX(Data!$B$2:$B$228,MATCH(6,Data!$J$2:$J$228,0)),"") | D11: =IFERROR(INDEX(Data!$C$2:$C$228,MATCH(6,Data!$J$2:$J$228,0)),"") | E11: =IFERROR(INDEX(Data!$D$2:$D$228,MATCH(6,Data!$J$2:$J$228,0)),"") | F11: =IFERROR(INDEX(Data!$E$2:$E$228,MATCH(6,Data!$J$2:$J$228,0)),"") | G11: =IFERROR(INDEX(Data!$F$2:$F$228,MATCH(6,Data!$J$2:$J$228,0)),"") | H11: =IFERROR(INDEX(Data!$G$2:$G$228,MATCH(6,Data!$J$2:$J$228,0)),"") | I11: =IFERROR(INDEX(Data!$H$2:$H$228,MATCH(6,Data!$J$2:$J$228,0)),"")
B12: =IFERROR(INDEX(Data!$A$2:$A$228,MATCH(7,Data!$J$2:$J$228,0)),"") | C12: =IFERROR(INDEX(Data!$B$2:$B$228,MATCH(7,Data!$J$2:$J$228,0)),"") | D12: =IFERROR(INDEX(Data!$C$2:$C$228,MATCH(7,Data!$J$2:$J$228,0)),"") | E12: =IFERROR(INDEX(Data!$D$2:$D$228,MATCH(7,Data!$J$2:$J$228,0)),"") | F12: =IFERROR(INDEX(Data!$E$2:$E$228,MATCH(7,Data!$J$2:$J$228,0)),"") | G12: =IFERROR(INDEX(Data!$F$2:$F$228,MATCH(7,Data!$J$2:$J$228,0)),"") | H12: =IFERROR(INDEX(Data!$G$2:$G$228,MATCH(7,Data!$J$2:$J$228,0)),"") | I12: =IFERROR(INDEX(Data!$H$2:$H$228,MATCH(7,Data!$J$2:$J$228,0)),"")
B13: =IFERROR(INDEX(Data!$A$2:$A$228,MATCH(8,Data!$J$2:$J$228,0)),"") | C13: =IFERROR(INDEX(Data!$B$2:$B$228,MATCH(8,Data!$J$2:$J$228,0)),"") | D13: =IFERROR(INDEX(Data!$C$2:$C$228,MATCH(8,Data!$J$2:$J$228,0)),"") | E13: =IFERROR(INDEX(Data!$D$2:$D$228,MATCH(8,Data!$J$2:$J$228,0)),"") | F13: =IFERROR(INDEX(Data!$E$2:$E$228,MATCH(8,Data!$J$2:$J$228,0)),"") | G13: =IFERROR(INDEX(Data!$F$2:$F$228,MATCH(8,Data!$J$2:$J$228,0)),"") | H13: =IFERROR(INDEX(Data!$G$2:$G$228,MATCH(8,Data!$J$2:$J$228,0)),"") | I13: =IFERROR(INDEX(Data!$H$2:$H$228,MATCH(8,Data!$J$2:$J$228,0)),"")
B14: =IFERROR(INDEX(Data!$A$2:$A$228,MATCH(9,Data!$J$2:$J$228,0)),"") | C14: =IFERROR(INDEX(Data!$B$2:$B$228,MATCH(9,Data!$J$2:$J$228,0)),"") | D14: =IFERROR(INDEX(Data!$C$2:$C$228,MATCH(9,Data!$J$2:$J$228,0)),"") | E14: =IFERROR(INDEX(Data!$D$2:$D$228,MATCH(9,Data!$J$2:$J$228,0)),"") | F14: =IFERROR(INDEX(Data!$E$2:$E$228,MATCH(9,Data!$J$2:$J$228,0)),"") | G14: =IFERROR(INDEX(Data!$F$2:$F$228,MATCH(9,Data!$J$2:$J$228,0)),"") | H14: =IFERROR(INDEX(Data!$G$2:$G$228,MATCH(9,Data!$J$2:$J$228,0)),"") | I14: =IFERROR(INDEX(Data!$H$2:$H$228,MATCH(9,Data!$J$2:$J$228,0)),"")
B15: =IFERROR(INDEX(Data!$A$2:$A$228,MATCH(10,Data!$J$2:$J$228,0)),"") | C15: =IFERROR(INDEX(Data!$B$2:$B$228,MATCH(10,Data!$J$2:$J$228,0)),"") | D15: =IFERROR(INDEX(Data!$C$2:$C$228,MATCH(10,Data!$J$2:$J$228,0)),"") | E15: =IFERROR(INDEX(Data!$D$2:$D$228,MATCH(10,Data!$J$2:$J$228,0)),"") | F15: =IFERROR(INDEX(Data!$E$2:$E$228,MATCH(10,Data!$J$2:$J$228,0)),"") | G15: =IFERROR(INDEX(Data!$F$2:$F$228,MATCH(10,Data!$J$2:$J$228,0)),"") | H15: =IFERROR(INDEX(Data!$G$2:$G$228,MATCH(10,Data!$J$2:$J$228,0)),"") | I15: =IFERROR(INDEX(Data!$H$2:$H$228,MATCH(10,Data!$J$2:$J$228,0)),"")
B16: =IFERROR(INDEX(Data!$A$2:$A$228,MATCH(11,Data!$J$2:$J$228,0)),"") | C16: =IFERROR(INDEX(Data!$B$2:$B$228,MATCH(11,Data!$J$2:$J$228,0)),"") | D16: =IFERROR(INDEX(Data!$C$2:$C$228,MATCH(11,Data!$J$2:$J$228,0)),"") | E16: =IFERROR(INDEX(Data!$D$2:$D$228,MATCH(11,Data!$J$2:$J$228,0)),"") | F16: =IFERROR(INDEX(Data!$E$2:$E$228,MATCH(11,Data!$J$2:$J$228,0)),"") | G16: =IFERROR(INDEX(Data!$F$2:$F$228,MATCH(11,Data!$J$2:$J$228,0)),"") | H16: =IFERROR(INDEX(Data!$G$2:$G$228,MATCH(11,Data!$J$2:$J$228,0)),"") | I16: =IFERROR(INDEX(Data!$H$2:$H$228,MATCH(11,Data!$J$2:$J$228,0)),"")
B17: =IFERROR(INDEX(Data!$A$2:$A$228,MATCH(12,Data!$J$2:$J$228,0)),"") | C17: =IFERROR(INDEX(Data!$B$2:$B$228,MATCH(12,Data!$J$2:$J$228,0)),"") | D17: =IFERROR(INDEX(Data!$C$2:$C$228,MATCH(12,Data!$J$2:$J$228,0)),"") | E17: =IFERROR(INDEX(Data!$D$2:$D$228,MATCH(12,Data!$J$2:$J$228,0)),"") | F17: =IFERROR(INDEX(Data!$E$2:$E$228,MATCH(12,Data!$J$2:$J$228,0)),"") | G17: =IFERROR(INDEX(Data!$F$2:$F$228,MATCH(12,Data!$J$2:$J$228,0)),"") | H17: =IFERROR(INDEX(Data!$G$2:$G$228,MATCH(12,Data!$J$2:$J$228,0)),"") | I17: =IFERROR(INDEX(Data!$H$2:$H$228,MATCH(12,Data!$J$2:$J$228,0)),"")
B18: =IFERROR(INDEX(Data!$A$2:$A$228,MATCH(13,Data!$J$2:$J$228,0)),"") | C18: =IFERROR(INDEX(Data!$B$2:$B$228,MATCH(13,Data!$J$2:$J$228,0)),"") | D18: =IFERROR(INDEX(Data!$C$2:$C$228,MATCH(13,Data!$J$2:$J$228,0)),"") | E18: =IFERROR(INDEX(Data!$D$2:$D$228,MATCH(13,Data!$J$2:$J$228,0)),"") | F18: =IFERROR(INDEX(Data!$E$2:$E$228,MATCH(13,Data!$J$2:$J$228,0)),"") | G18: =IFERROR(INDEX(Data!$F$2:$F$228,MATCH(13,Data!$J$2:$J$228,0)),"") | H18: =IFERROR(INDEX(Data!$G$2:$G$228,MATCH(13,Data!$J$2:$J$228,0)),"") | I18: =IFERROR(INDEX(Data!$H$2:$H$228,MATCH(13,Data!$J$2:$J$228,0)),"")
B19: =IFERROR(INDEX(Data!$A$2:$A$228,MATCH(14,Data!$J$2:$J$228,0)),"") | C19: =IFERROR(INDEX(Data!$B$2:$B$228,MATCH(14,Data!$J$2:$J$228,0)),"") | D19: =IFERROR(INDEX(Data!$C$2:$C$228,MATCH(14,Data!$J$2:$J$228,0)),"") | E19: =IFERROR(INDEX(Data!$D$2:$D$228,MATCH(14,Data!$J$2:$J$228,0)),"") | F19: =IFERROR(INDEX(Data!$E$2:$E$228,MATCH(14,Data!$J$2:$J$228,0)),"") | G19: =IFERROR(INDEX(Data!$F$2:$F$228,MATCH(14,Data!$J$2:$J$228,0)),"") | H19: =IFERROR(INDEX(Data!$G$2:$G$228,MATCH(14,Data!$J$2:$J$228,0)),"") | I19: =IFERROR(INDEX(Data!$H$2:$H$228,MATCH(14,Data!$J$2:$J$228,0)),"")
B20: =IFERROR(INDEX(Data!$A$2:$A$228,MATCH(15,Data!$J$2:$J$228,0)),"") | C20: =IFERROR(INDEX(Data!$B$2:$B$228,MATCH(15,Data!$J$2:$J$228,0)),"") | D20: =IFERROR(INDEX(Data!$C$2:$C$228,MATCH(15,Data!$J$2:$J$228,0)),"") | E20: =IFERROR(INDEX(Data!$D$2:$D$228,MATCH(15,Data!$J$2:$J$228,0)),"") | F20: =IFERROR(INDEX(Data!$E$2:$E$228,MATCH(15,Data!$J$2:$J$228,0)),"") | G20: =IFERROR(INDEX(Data!$F$2:$F$228,MATCH(15,Data!$J$2:$J$228,0)),"") | H20: =IFERROR(INDEX(Data!$G$2:$G$228,MATCH(15,Data!$J$2:$J$228,0)),"") | I20: =IFERROR(INDEX(Data!$H$2:$H$228,MATCH(15,Data!$J$2:$J$228,0)),"")
B21: =IFERROR(INDEX(Data!$A$2:$A$228,MATCH(16,Data!$J$2:$J$228,0)),"") | C21: =IFERROR(INDEX(Data!$B$2:$B$228,MATCH(16,Data!$J$2:$J$228,0)),"") | D21: =IFERROR(INDEX(Data!$C$2:$C$228,MATCH(16,Data!$J$2:$J$228,0)),"") | E21: =IFERROR(INDEX(Data!$D$2:$D$228,MATCH(16,Data!$J$2:$J$228,0)),"") | F21: =IFERROR(INDEX(Data!$E$2:$E$228,MATCH(16,Data!$J$2:$J$228,0)),"") | G21: =IFERROR(INDEX(Data!$F$2:$F$228,MATCH(16,Data!$J$2:$J$228,0)),"") | H21: =IFERROR(INDEX(Data!$G$2:$G$228,MATCH(16,Data!$J$2:$J$228,0)),"") | I21: =IFERROR(INDEX(Data!$H$2:$H$228,MATCH(16,Data!$J$2:$J$228,0)),"")
B22: =IFERROR(INDEX(Data!$A$2:$A$228,MATCH(17,Data!$J$2:$J$228,0)),"") | C22: =IFERROR(INDEX(Data!$B$2:$B$228,MATCH(17,Data!$J$2:$J$228,0)),"") | D22: =IFERROR(INDEX(Data!$C$2:$C$228,MATCH(17,Data!$J$2:$J$228,0)),"") | E22: =IFERROR(INDEX(Data!$D$2:$D$228,MATCH(17,Data!$J$2:$J$228,0)),"") | F22: =IFERROR(INDEX(Data!$E$2:$E$228,MATCH(17,Data!$J$2:$J$228,0)),"") | G22: =IFERROR(INDEX(Data!$F$2:$F$228,MATCH(17,Data!$J$2:$J$228,0)),"") | H22: =IFERROR(INDEX(Data!$G$2:$G$228,MATCH(17,Data!$J$2:$J$228,0)),"") | I22: =IFERROR(INDEX(Data!$H$2:$H$228,MATCH(17,Data!$J$2:$J$228,0)),"")
B23: =IFERROR(INDEX(Data!$A$2:$A$228,MATCH(18,Data!$J$2:$J$228,0)),"") | C23: =IFERROR(INDEX(Data!$B$2:$B$228,MATCH(18,Data!$J$2:$J$228,0)),"") | D23: =IFERROR(INDEX(Data!$C$2:$C$228,MATCH(18,Data!$J$2:$J$228,0)),"") | E23: =IFERROR(INDEX(Data!$D$2:$D$228,MATCH(18,Data!$J$2:$J$228,0)),"") | F23: =IFERROR(INDEX(Data!$E$2:$E$228,MATCH(18,Data!$J$2:$J$228,0)),"") | G23: =IFERROR(INDEX(Data!$F$2:$F$228,MATCH(18,Data!$J$2:$J$228,0)),"") | H23: =IFERROR(INDEX(Data!$G$2:$G$228,MATCH(18,Data!$J$2:$J$228,0)),"") | I23: =IFERROR(INDEX(Data!$H$2:$H$228,MATCH(18,Data!$J$2:$J$228,0)),"")
B24: =IFERROR(INDEX(Data!$A$2:$A$228,MATCH(19,Data!$J$2:$J$228,0)),"") | C24: =IFERROR(INDEX(Data!$B$2:$B$228,MATCH(19,Data!$J$2:$J$228,0)),"") | D24: =IFERROR(INDEX(Data!$C$2:$C$228,MATCH(19,Data!$J$2:$J$228,0)),"") | E24: =IFERROR(INDEX(Data!$D$2:$D$228,MATCH(19,Data!$J$2:$J$228,0)),"") | F24: =IFERROR(INDEX(Data!$E$2:$E$228,MATCH(19,Data!$J$2:$J$228,0)),"") | G24: =IFERROR(INDEX(Data!$F$2:$F$228,MATCH(19,Data!$J$2:$J$228,0)),"") | H24: =IFERROR(INDEX(Data!$G$2:$G$228,MATCH(19,Data!$J$2:$J$228,0)),"") | I24: =IFERROR(INDEX(Data!$H$2:$H$228,MATCH(19,Data!$J$2:$J$228,0)),"")
B25: =IFERROR(INDEX(Data!$A$2:$A$228,MATCH(20,Data!$J$2:$J$228,0)),"") | C25: =IFERROR(INDEX(Data!$B$2:$B$228,MATCH(20,Data!$J$2:$J$228,0)),"") | D25: =IFERROR(INDEX(Data!$C$2:$C$228,MATCH(20,Data!$J$2:$J$228,0)),"") | E25: =IFERROR(INDEX(Data!$D$2:$D$228,MATCH(20,Data!$J$2:$J$228,0)),"") | F25: =IFERROR(INDEX(Data!$E$2:$E$228,MATCH(20,Data!$J$2:$J$228,0)),"") | G25: =IFERROR(INDEX(Data!$F$2:$F$228,MATCH(20,Data!$J$2:$J$228,0)),"") | H25: =IFERROR(INDEX(Data!$G$2:$G$228,MATCH(20,Data!$J$2:$J$228,0)),"") | I25: =IFERROR(INDEX(Data!$H$2:$H$228,MATCH(20,Data!$J$2:$J$228,0)),"")
B26: =IFERROR(INDEX(Data!$A$2:$A$228,MATCH(21,Data!$J$2:$J$228,0)),"") | C26: =IFERROR(INDEX(Data!$B$2:$B$228,MATCH(21,Data!$J$2:$J$228,0)),"") | D26: =IFERROR(INDEX(Data!$C$2:$C$228,MATCH(21,Data!$J$2:$J$228,0)),"") | E26: =IFERROR(INDEX(Data!$D$2:$D$228,MATCH(21,Data!$J$2:$J$228,0)),"") | F26: =IFERROR(INDEX(Data!$E$2:$E$228,MATCH(21,Data!$J$2:$J$228,0)),"") | G26: =IFERROR(INDEX(Data!$F$2:$F$228,MATCH(21,Data!$J$2:$J$228,0)),"") | H26: =IFERROR(INDEX(Data!$G$2:$G$228,MATCH(21,Data!$J$2:$J$228,0)),"") | I26: =IFERROR(INDEX(Data!$H$2:$H$228,MATCH(21,Data!$J$2:$J$228,0)),"")
B27: =IFERROR(INDEX(Data!$A$2:$A$228,MATCH(22,Data!$J$2:$J$228,0)),"") | C27: =IFERROR(INDEX(Data!$B$2:$B$228,MATCH(22,Data!$J$2:$J$228,0)),"") | D27: =IFERROR(INDEX(Data!$C$2:$C$228,MATCH(22,Data!$J$2:$J$228,0)),"") | E27: =IFERROR(INDEX(Data!$D$2:$D$228,MATCH(22,Data!$J$2:$J$228,0)),"") | F27: =IFERROR(INDEX(Data!$E$2:$E$228,MATCH(22,Data!$J$2:$J$228,0)),"") | G27: =IFERROR(INDEX(Data!$F$2:$F$228,MATCH(22,Data!$J$2:$J$228,0)),"") | H27: =IFERROR(INDEX(Data!$G$2:$G$228,MATCH(22,Data!$J$2:$J$228,0)),"") | I27: =IFERROR(INDEX(Data!$H$2:$H$228,MATCH(22,Data!$J$2:$J$228,0)),"")
B28: =IFERROR(INDEX(Data!$A$2:$A$228,MATCH(23,Data!$J$2:$J$228,0)),"") | C28: =IFERROR(INDEX(Data!$B$2:$B$228,MATCH(23,Data!$J$2:$J$228,0)),"") | D28: =IFERROR(INDEX(Data!$C$2:$C$228,MATCH(23,Data!$J$2:$J$228,0)),"") | E28: =IFERROR(INDEX(Data!$D$2:$D$228,MATCH(23,Data!$J$2:$J$228,0)),"") | F28: =IFERROR(INDEX(Data!$E$2:$E$228,MATCH(23,Data!$J$2:$J$228,0)),"") | G28: =IFERROR(INDEX(Data!$F$2:$F$228,MATCH(23,Data!$J$2:$J$228,0)),"") | H28: =IFERROR(INDEX(Data!$G$2:$G$228,MATCH(23,Data!$J$2:$J$228,0)),"") | I28: =IFERROR(INDEX(Data!$H$2:$H$228,MATCH(23,Data!$J$2:$J$228,0)),"")
B29: =IFERROR(INDEX(Data!$A$2:$A$228,MATCH(24,Data!$J$2:$J$228,0)),"") | C29: =IFERROR(INDEX(Data!$B$2:$B$228,MATCH(24,Data!$J$2:$J$228,0)),"") | D29: =IFERROR(INDEX(Data!$C$2:$C$228,MATCH(24,Data!$J$2:$J$228,0)),"") | E29: =IFERROR(INDEX(Data!$D$2:$D$228,MATCH(24,Data!$J$2:$J$228,0)),"") | F29: =IFERROR(INDEX(Data!$E$2:$E$228,MATCH(24,Data!$J$2:$J$228,0)),"") | G29: =IFERROR(INDEX(Data!$F$2:$F$228,MATCH(24,Data!$J$2:$J$228,0)),"") | H29: =IFERROR(INDEX(Data!$G$2:$G$228,MATCH(24,Data!$J$2:$J$228,0)),"") | I29: =IFERROR(INDEX(Data!$H$2:$H$228,MATCH(24,Data!$J$2:$J$228,0)),"")
B30: =IFERROR(INDEX(Data!$A$2:$A$228,MATCH(25,Data!$J$2:$J$228,0)),"") | C30: =IFERROR(INDEX(Data!$B$2:$B$228,MATCH(25,Data!$J$2:$J$228,0)),"") | D30: =IFERROR(INDEX(Data!$C$2:$C$228,MATCH(25,Data!$J$2:$J$228,0)),"") | E30: =IFERROR(INDEX(Data!$D$2:$D$228,MATCH(25,Data!$J$2:$J$228,0)),"") | F30: =IFERROR(INDEX(Data!$E$2:$E$228,MATCH(25,Data!$J$2:$J$228,0)),"") | G30: =IFERROR(INDEX(Data!$F$2:$F$228,MATCH(25,Data!$J$2:$J$228,0)),"") | H30: =IFERROR(INDEX(Data!$G$2:$G$228,MATCH(25,Data!$J$2:$J$228,0)),"") | I30: =IFERROR(INDEX(Data!$H$2:$H$228,MATCH(25,Data!$J$2:$J$228,0)),"")
B31: =IFERROR(INDEX(Data!$A$2:$A$228,MATCH(26,Data!$J$2:$J$228,0)),"") | C31: =IFERROR(INDEX(Data!$B$2:$B$228,MATCH(26,Data!$J$2:$J$228,0)),"") | D31: =IFERROR(INDEX(Data!$C$2:$C$228,MATCH(26,Data!$J$2:$J$228,0)),"") | E31: =IFERROR(INDEX(Data!$D$2:$D$228,MATCH(26,Data!$J$2:$J$228,0)),"") | F31: =IFERROR(INDEX(Data!$E$2:$E$228,MATCH(26,Data!$J$2:$J$228,0)),"") | G31: =IFERROR(INDEX(Data!$F$2:$F$228,MATCH(26,Data!$J$2:$J$228,0)),"") | H31: =IFERROR(INDEX(Data!$G$2:$G$228,MATCH(26,Data!$J$2:$J$228,0)),"") | I31: =IFERROR(INDEX(Data!$H$2:$H$228,MATCH(26,Data!$J$2:$J$228,0)),"")
B32: =IFERROR(INDEX(Data!$A$2:$A$228,MATCH(27,Data!$J$2:$J$228,0)),"") | C32: =IFERROR(INDEX(Data!$B$2:$B$228,MATCH(27,Data!$J$2:$J$228,0)),"") | D32: =IFERROR(INDEX(Data!$C$2:$C$228,MATCH(27,Data!$J$2:$J$228,0)),"") | E32: =IFERROR(INDEX(Data!$D$2:$D$228,MATCH(27,Data!$J$2:$J$228,0)),"") | F32: =IFERROR(INDEX(Data!$E$2:$E$228,MATCH(27,Data!$J$2:$J$228,0)),"") | G32: =IFERROR(INDEX(Data!$F$2:$F$228,MATCH(27,Data!$J$2:$J$228,0)),"") | H32: =IFERROR(INDEX(Data!$G$2:$G$228,MATCH(27,Data!$J$2:$J$228,0)),"") | I32: =IFERROR(INDEX(Data!$H$2:$H$228,MATCH(27,Data!$J$2:$J$228,0)),"")
B33: =IFERROR(INDEX(Data!$A$2:$A$228,MATCH(28,Data!$J$2:$J$228,0)),"") | C33: =IFERROR(INDEX(Data!$B$2:$B$228,MATCH(28,Data!$J$2:$J$228,0)),"") | D33: =IFERROR(INDEX(Data!$C$2:$C$228,MATCH(28,Data!$J$2:$J$228,0)),"") | E33: =IFERROR(INDEX(Data!$D$2:$D$228,MATCH(28,Data!$J$2:$J$228,0)),"") | F33: =IFERROR(INDEX(Data!$E$2:$E$228,MATCH(28,Data!$J$2:$J$228,0)),"") | G33: =IFERROR(INDEX(Data!$F$2:$F$228,MATCH(28,Data!$J$2:$J$228,0)),"") | H33: =IFERROR(INDEX(Data!$G$2:$G$228,MATCH(28,Data!$J$2:$J$228,0)),"") | I33: =IFERROR(INDEX(Data!$H$2:$H$228,MATCH(28,Data!$J$2:$J$228,0)),"")
B34: =IFERROR(INDEX(Data!$A$2:$A$228,MATCH(29,Data!$J$2:$J$228,0)),"") | C34: =IFERROR(INDEX(Data!$B$2:$B$228,MATCH(29,Data!$J$2:$J$228,0)),"") | D34: =IFERROR(INDEX(Data!$C$2:$C$228,MATCH(29,Data!$J$2:$J$228,0)),"") | E34: =IFERROR(INDEX(Data!$D$2:$D$228,MATCH(29,Data!$J$2:$J$228,0)),"") | F34: =IFERROR(INDEX(Data!$E$2:$E$228,MATCH(29,Data!$J$2:$J$228,0)),"") | G34: =IFERROR(INDEX(Data!$F$2:$F$228,MATCH(29,Data!$J$2:$J$228,0)),"") | H34: =IFERROR(INDEX(Data!$G$2:$G$228,MATCH(29,Data!$J$2:$J$228,0)),"") | I34: =IFERROR(INDEX(Data!$H$2:$H$228,MATCH(29,Data!$J$2:$J$228,0)),"")
B35: =IFERROR(INDEX(Data!$A$2:$A$228,MATCH(30,Data!$J$2:$J$228,0)),"") | C35: =IFERROR(INDEX(Data!$B$2:$B$228,MATCH(30,Data!$J$2:$J$228,0)),"") | D35: =IFERROR(INDEX(Data!$C$2:$C$228,MATCH(30,Data!$J$2:$J$228,0)),"") | E35: =IFERROR(INDEX(Data!$D$2:$D$228,MATCH(30,Data!$J$2:$J$228,0)),"") | F35: =IFERROR(INDEX(Data!$E$2:$E$228,MATCH(30,Data!$J$2:$J$228,0)),"") | G35: =IFERROR(INDEX(Data!$F$2:$F$228,MATCH(30,Data!$J$2:$J$228,0)),"") | H35: =IFERROR(INDEX(Data!$G$2:$G$228,MATCH(30,Data!$J$2:$J$228,0)),"") | I35: =IFERROR(INDEX(Data!$H$2:$H$228,MATCH(30,Data!$J$2:$J$228,0)),"")
B36: =IFERROR(INDEX(Data!$A$2:$A$228,MATCH(31,Data!$J$2:$J$228,0)),"") | C36: =IFERROR(INDEX(Data!$B$2:$B$228,MATCH(31,Data!$J$2:$J$228,0)),"") | D36: =IFERROR(INDEX(Data!$C$2:$C$228,MATCH(31,Data!$J$2:$J$228,0)),"") | E36: =IFERROR(INDEX(Data!$D$2:$D$228,MATCH(31,Data!$J$2:$J$228,0)),"") | F36: =IFERROR(INDEX(Data!$E$2:$E$228,MATCH(31,Data!$J$2:$J$228,0)),"") | G36: =IFERROR(INDEX(Data!$F$2:$F$228,MATCH(31,Data!$J$2:$J$228,0)),"") | H36: =IFERROR(INDEX(Data!$G$2:$G$228,MATCH(31,Data!$J$2:$J$228,0)),"") | I36: =IFERROR(INDEX(Data!$H$2:$H$228,MATCH(31,Data!$J$2:$J$228,0)),"")
B37: =IFERROR(INDEX(Data!$A$2:$A$228,MATCH(32,Data!$J$2:$J$228,0)),"") | C37: =IFERROR(INDEX(Data!$B$2:$B$228,MATCH(32,Data!$J$2:$J$228,0)),"") | D37: =IFERROR(INDEX(Data!$C$2:$C$228,MATCH(32,Data!$J$2:$J$228,0)),"") | E37: =IFERROR(INDEX(Data!$D$2:$D$228,MATCH(32,Data!$J$2:$J$228,0)),"") | F37: =IFERROR(INDEX(Data!$E$2:$E$228,MATCH(32,Data!$J$2:$J$228,0)),"") | G37: =IFERROR(INDEX(Data!$F$2:$F$228,MATCH(32,Data!$J$2:$J$228,0)),"") | H37: =IFERROR(INDEX(Data!$G$2:$G$228,MATCH(32,Data!$J$2:$J$228,0)),"") | I37: =IFERROR(INDEX(Data!$H$2:$H$228,MATCH(32,Data!$J$2:$J$228,0)),"")
B38: =IFERROR(INDEX(Data!$A$2:$A$228,MATCH(33,Data!$J$2:$J$228,0)),"") | C38: =IFERROR(INDEX(Data!$B$2:$B$228,MATCH(33,Data!$J$2:$J$228,0)),"") | D38: =IFERROR(INDEX(Data!$C$2:$C$228,MATCH(33,Data!$J$2:$J$228,0)),"") | E38: =IFERROR(INDEX(Data!$D$2:$D$228,MATCH(33,Data!$J$2:$J$228,0)),"") | F38: =IFERROR(INDEX(Data!$E$2:$E$228,MATCH(33,Data!$J$2:$J$228,0)),"") | G38: =IFERROR(INDEX(Data!$F$2:$F$228,MATCH(33,Data!$J$2:$J$228,0)),"") | H38: =IFERROR(INDEX(Data!$G$2:$G$228,MATCH(33,Data!$J$2:$J$228,0)),"") | I38: =IFERROR(INDEX(Data!$H$2:$H$228,MATCH(33,Data!$J$2:$J$228,0)),"")
B39: =IFERROR(INDEX(Data!$A$2:$A$228,MATCH(34,Data!$J$2:$J$228,0)),"") | C39: =IFERROR(INDEX(Data!$B$2:$B$228,MATCH(34,Data!$J$2:$J$228,0)),"") | D39: =IFERROR(INDEX(Data!$C$2:$C$228,MATCH(34,Data!$J$2:$J$228,0)),"") | E39: =IFERROR(INDEX(Data!$D$2:$D$228,MATCH(34,Data!$J$2:$J$228,0)),"") | F39: =IFERROR(INDEX(Data!$E$2:$E$228,MATCH(34,Data!$J$2:$J$228,0)),"") | G39: =IFERROR(INDEX(Data!$F$2:$F$228,MATCH(34,Data!$J$2:$J$228,0)),"") | H39: =IFERROR(INDEX(Data!$G$2:$G$228,MATCH(34,Data!$J$2:$J$228,0)),"") | I39: =IFERROR(INDEX(Data!$H$2:$H$228,MATCH(34,Data!$J$2:$J$228,0)),"")
B40: =IFERROR(INDEX(Data!$A$2:$A$228,MATCH(35,Data!$J$2:$J$228,0)),"") | C40: =IFERROR(INDEX(Data!$B$2:$B$228,MATCH(35,Data!$J$2:$J$228,0)),"") | D40: =IFERROR(INDEX(Data!$C$2:$C$228,MATCH(35,Data!$J$2:$J$228,0)),"") | E40: =IFERROR(INDEX(Data!$D$2:$D$228,MATCH(35,Data!$J$2:$J$228,0)),"") | F40: =IFERROR(INDEX(Data!$E$2:$E$228,MATCH(35,Data!$J$2:$J$228,0)),"") | G40: =IFERROR(INDEX(Data!$F$2:$F$228,MATCH(35,Data!$J$2:$J$228,0)),"") | H40: =IFERROR(INDEX(Data!$G$2:$G$228,MATCH(35,Data!$J$2:$J$228,0)),"") | I40: =IFERROR(INDEX(Data!$H$2:$H$228,MATCH(35,Data!$J$2:$J$228,0)),"")
B41: =IFERROR(INDEX(Data!$A$2:$A$228,MATCH(36,Data!$J$2:$J$228,0)),"") | C41: =IFERROR(INDEX(Data!$B$2:$B$228,MATCH(36,Data!$J$2:$J$228,0)),"") | D41: =IFERROR(INDEX(Data!$C$2:$C$228,MATCH(36,Data!$J$2:$J$228,0)),"") | E41: =IFERROR(INDEX(Data!$D$2:$D$228,MATCH(36,Data!$J$2:$J$228,0)),"") | F41: =IFERROR(INDEX(Data!$E$2:$E$228,MATCH(36,Data!$J$2:$J$228,0)),"") | G41: =IFERROR(INDEX(Data!$F$2:$F$228,MATCH(36,Data!$J$2:$J$228,0)),"") | H41: =IFERROR(INDEX(Data!$G$2:$G$228,MATCH(36,Data!$J$2:$J$228,0)),"") | I41: =IFERROR(INDEX(Data!$H$2:$H$228,MATCH(36,Data!$J$2:$J$228,0)),"")
...

Sheet Data
A1: Generic | B1: Therapeutic class | C1: Common forms & strengths | D1: Alternatives (same class / therapeutic) | E1: Brand examples — India | F1: Brand examples — UAE / GCC | G1: ATC | H1: Procurement note | I1: match | J1: n
A2: 5-Fluorouracil | B2: Antimetabolite chemotherapy | C2: 250 mg/5 ml, 500 mg/10 ml inj | D2: Capecitabine (oral prodrug) | E2: Fluracil, 5-FU (various) | F2: 5-FU (various) | G2: L01BC02 | H2: Cytotoxic. | I2: =IF(Lookup!$B$3="",FALSE(),ISNUMBER(SEARCH(Lookup!$B$3,A2&" "&B2&" "&D2&" "&E2&" "&F2))) -> FALSE | J2: =IF(I2,COUNTIF($I$2:I2,TRUE()),"")
A3: Acyclovir | B3: Antiviral | C3: 400/800 mg tab; 250/500 mg inj; 5% cream | D3: Valacyclovir (oral); Famciclovir | E3: Zovirax, Acivir | F3: Zovirax, Acyclovir (various) | G3: J05AB01 | I3: =IF(Lookup!$B$3="",FALSE(),ISNUMBER(SEARCH(Lookup!$B$3,A3&" "&B3&" "&D3&" "&E3&" "&F3))) -> FALSE | J3: =IF(I3,COUNTIF($I$2:I3,TRUE()),"")
A4: Adalimumab | B4: TNF inhibitor | C4: 40 mg prefilled pen/syringe | D4: Adalimumab biosimilars; Etanercept; Infliximab | E4: Exemptia, Adfrar (biosimilars) | F4: Humira, Hyrimoz/Idacio (biosimilars) | G4: L04AB04 | H4: Biosimilar switch programmes save 40–70%. | I4: =IF(Lookup!$B$3="",FALSE(),ISNUMBER(SEARCH(Lookup!$B$3,A4&" "&B4&" "&D4&" "&E4&" "&F4))) -> FALSE | J4: =IF(I4,COUNTIF($I$2:I4,TRUE()),"")
A5: Adrenaline (epinephrine) | B5: Vasopressor / emergency | C5: 1 mg/ml inj; auto-injector | D5: Noradrenaline (vasopressor); (emergency use unique) | E5: Adrenaline (various), Vasocon | F5: Adrenaline (various), EpiPen (auto-injector) | G5: C01CA24 | H5: Crash-cart item — expiry management critical. | I5: =IF(Lookup!$B$3="",FALSE(),ISNUMBER(SEARCH(Lookup!$B$3,A5&" "&B5&" "&D5&" "&E5&" "&F5))) -> FALSE | J5: =IF(I5,COUNTIF($I$2:I5,TRUE()),"")
A6: Albendazole | B6: Anthelmintic | C6: 400 mg tab; suspension | D6: Mebendazole; Ivermectin (per indication) | E6: Zentel, Bandy | F6: Zentel, Albendazole (various) | G6: P02CA03 | I6: =IF(Lookup!$B$3="",FALSE(),ISNUMBER(SEARCH(Lookup!$B$3,A6&" "&B6&" "&D6&" "&E6&" "&F6))) -> FALSE | J6: =IF(I6,COUNTIF($I$2:I6,TRUE()),"")
A7: Albumin 20% | B7: Plasma expander | C7: 50/100 ml | D7: Albumin 5%; Synthetic colloids (restricted) | E7: Albumin (various), Alburel | F7: Albumin (various), Albutein | G7: B05AA01 | H7: Plasma-derived; cold chain; batch documentation. | I7: =IF(Lookup!$B$3="",FALSE(),ISNUMBER(SEARCH(Lookup!$B$3,A7&" "&B7&" "&D7&" "&E7&" "&F7))) -> FALSE | J7: =IF(I7,COUNTIF($I$2:I7,TRUE()),"")
A8: Allopurinol | B8: Xanthine oxidase inhibitor | C8: 100/300 mg tab | D8: Febuxostat | E8: Zyloric, Zyloprim | F8: Zyloric, Allopurinol (various) | G8: M04AA01 | I8: =IF(Lookup!$B$3="",FALSE(),ISNUMBER(SEARCH(Lookup!$B$3,A8&" "&B8&" "&D8&" "&E8&" "&F8))) -> FALSE | J8: =IF(I8,COUNTIF($I$2:I8,TRUE()),"")
A9: Alprazolam | B9: Benzodiazepine (anxiolytic) | C9: 0.25/0.5/1 mg tab | D9: Lorazepam; Clonazepam; Diazepam | E9: Alprax, Restyl | F9: Xanax | G9: N05BA12 | H9: Controlled. | I9: =IF(Lookup!$B$3="",FALSE(),ISNUMBER(SEARCH(Lookup!$B$3,A9&" "&B9&" "&D9&" "&E9&" "&F9))) -> FALSE | J9: =IF(I9,COUNTIF($I$2:I9,TRUE()),"")
A10: Amikacin | B10: Aminoglycoside antibiotic | C10: 500 mg/2 ml inj | D10: Gentamicin; Tobramycin | E10: Mikacin, Amicin | F10: Amikin, Amikacin (various) | G10: J01GB06 | I10: =IF(Lookup!$B$3="",FALSE(),ISNUMBER(SEARCH(Lookup!$B$3,A10&" "&B10&" "&D10&" "&E10&" "&F10))) -> FALSE | J10: =IF(I10,COUNTIF($I$2:I10,TRUE()),"")
A11: Amiodarone | B11: Antiarrhythmic | C11: 100/200 mg tab; 150 mg/3 ml inj | D11: (Limited) Flecainide / sotalol per indication | E11: Cordarone, Amiodar | F11: Cordarone, Amiodarone (various) | G11: C01BD01 | I11: =IF(Lookup!$B$3="",FALSE(),ISNUMBER(SEARCH(Lookup!$B$3,A11&" "&B11&" "&D11&" "&E11&" "&F11))) -> FALSE | J11: =IF(I11,COUNTIF($I$2:I11,TRUE()),"")
A12: Amitriptyline | B12: Tricyclic antidepressant | C12: 10/25/75 mg tab | D12: Nortriptyline; Duloxetine (pain) | E12: Tryptomer, Amitor | F12: Tryptizol, Amitriptyline (various) | G12: N06AA09 | I12: =IF(Lookup!$B$3="",FALSE(),ISNUMBER(SEARCH(Lookup!$B$3,A12&" "&B12&" "&D12&" "&E12&" "&F12))) -> FALSE | J12: =IF(I12,COUNTIF($I$2:I12,TRUE()),"")
A13: Amlodipine | B13: Calcium channel blocker | C13: 2.5/5/10 mg tab | D13: Nifedipine (ER); Cilnidipine; Felodipine | E13: Amlong, Amlokind, Stamlo | F13: Norvasc, Amlor | G13: C08CA01 | H13: Commodity generic. | I13: =IF(Lookup!$B$3="",FALSE(),ISNUMBER(SEARCH(Lookup!$B$3,A13&" "&B13&" "&D13&" "&E13&" "&F13))) -> FALSE | J13: =IF(I13,COUNTIF($I$2:I13,TRUE()),"")
A14: Amoxicillin | B14: Penicillin antibiotic | C14: 250/500 mg cap; 125–250 mg/5 ml susp | D14: Amoxicillin-clavulanate; Cefalexin; Azithromycin (per indication) | E14: Mox, Novamox | F14: Amoxil, Julphamox | G14: J01CA04 | I14: =IF(Lookup!$B$3="",FALSE(),ISNUMBER(SEARCH(Lookup!$B$3,A14&" "&B14&" "&D14&" "&E14&" "&F14))) -> FALSE | J14: =IF(I14,COUNTIF($I$2:I14,TRUE()),"")
A15: Amoxicillin-clavulanate | B15: Penicillin + beta-lactamase inhibitor | C15: 625 mg, 1 g tab; 1.2 g inj; 228–457 mg/5 ml susp | D15: Cefuroxime; Ampicillin-sulbactam; Piperacillin-tazobactam (severe) | E15: Augmentin, Clavam, Moxikind-CV | F15: Augmentin, Curam, Klavox | G15: J01CR02 | H15: Highest-spend oral antibiotic in most hospitals; generic availability wide. | I15: =IF(Lookup!$B$3="",FALSE(),ISNUMBER(SEARCH(Lookup!$B$3,A15&" "&B15&" "&D15&" "&E15&" "&F15))) -> FALSE | J15: =IF(I15,COUNTIF($I$2:I15,TRUE()),"")
A16: Amphotericin B (liposomal) | B16: Polyene antifungal | C16: 50 mg inj | D16: Conventional amphotericin B; Caspofungin / Micafungin | E16: AmBisome, Fungisome | F16: AmBisome | G16: J02AA01 | H16: Specialist; cold chain. | I16: =IF(Lookup!$B$3="",FALSE(),ISNUMBER(SEARCH(Lookup!$B$3,A16&" "&B16&" "&D16&" "&E16&" "&F16))) -> FALSE | J16: =IF(I16,COUNTIF($I$2:I16,TRUE()),"")
A17: Anti-D immunoglobulin | B17: Immunoglobulin | C17: 300 mcg (1500 IU) inj | D17: (Product-specific) | E17: Rhoclone, Rhogam | F17: Rhophylac, Rhogam | G17: J06BB01 | H17: Cold chain; obstetrics. | I17: =IF(Lookup!$B$3="",FALSE(),ISNUMBER(SEARCH(Lookup!$B$3,A17&" "&B17&" "&D17&" "&E17&" "&F17))) -> FALSE | J17: =IF(I17,COUNTIF($I$2:I17,TRUE()),"")
A18: Apixaban | B18: Direct oral anticoagulant | C18: 2.5/5 mg tab | D18: Rivaroxaban; Dabigatran; Warfarin | E18: Eliquis, Apixabid | F18: Eliquis | G18: B01AF02 | H18: Generics in India; originator in GCC — large price gap. | I18: =IF(Lookup!$B$3="",FALSE(),ISNUMBER(SEARCH(Lookup!$B$3,A18&" "&B18&" "&D18&" "&E18&" "&F18))) -> FALSE | J18: =IF(I18,COUNTIF($I$2:I18,TRUE()),"")
A19: Artemether-lumefantrine | B19: Antimalarial (ACT) | C19: 20/120 mg tab | D19: Artesunate (IV, severe); Artesunate-mefloquine | E19: Lumerax, Lumartem | F19: Coartem, Riamet | G19: P01BF01 | I19: =IF(Lookup!$B$3="",FALSE(),ISNUMBER(SEARCH(Lookup!$B$3,A19&" "&B19&" "&D19&" "&E19&" "&F19))) -> FALSE | J19: =IF(I19,COUNTIF($I$2:I19,TRUE()),"")
A20: Artesunate | B20: Antimalarial (severe) | C20: 60 mg inj; 50/100 mg tab | D20: Quinine (IV); Artemether (IM) | E20: Falcigo, Larinate | F20: Artesunate (various) | G20: P01BE03 | I20: =IF(Lookup!$B$3="",FALSE(),ISNUMBER(SEARCH(Lookup!$B$3,A20&" "&B20&" "&D20&" "&E20&" "&F20))) -> FALSE | J20: =IF(I20,COUNTIF($I$2:I20,TRUE()),"")
A21: Aspirin (low dose) | B21: Antiplatelet | C21: 75/81/100/150 mg tab | D21: Clopidogrel (where aspirin not tolerated) | E21: Ecosprin, Loprin | F21: Aspirin Protect, Jusprin | G21: B01AC06 | I21: =IF(Lookup!$B$3="",FALSE(),ISNUMBER(SEARCH(Lookup!$B$3,A21&" "&B21&" "&D21&" "&E21&" "&F21))) -> FALSE | J21: =IF(I21,COUNTIF($I$2:I21,TRUE()),"")
A22: Atenolol | B22: Beta blocker | C22: 25/50/100 mg tab | D22: Metoprolol; Bisoprolol | E22: Aten, Tenormin | F22: Tenormin | G22: C07AB03 | I22: =IF(Lookup!$B$3="",FALSE(),ISNUMBER(SEARCH(Lookup!$B$3,A22&" "&B22&" "&D22&" "&E22&" "&F22))) -> FALSE | J22: =IF(I22,COUNTIF($I$2:I22,TRUE()),"")
A23: Atorvastatin | B23: Statin | C23: 10/20/40/80 mg tab | D23: Rosuvastatin; Simvastatin; Pravastatin | E23: Atorva, Lipicure, Storvas | F23: Lipitor, Atorvastatin (various) | G23: C10AA05 | H23: Commodity generic — tender per 10 mg-equivalent. | I23: =IF(Lookup!$B$3="",FALSE(),ISNUMBER(SEARCH(Lookup!$B$3,A23&" "&B23&" "&D23&" "&E23&" "&F23))) -> FALSE | J23: =IF(I23,COUNTIF($I$2:I23,TRUE()),"")
A24: Atracurium | B24: Neuromuscular blocker | C24: 10 mg/ml inj | D24: Cisatracurium; Rocuronium; Vecuronium | E24: Tracrium, Atrabim | F24: Tracrium, Atracurium (various) | G24: M03AC04 | H24: Cold chain. | I24: =IF(Lookup!$B$3="",FALSE(),ISNUMBER(SEARCH(Lookup!$B$3,A24&" "&B24&" "&D24&" "&E24&" "&F24))) -> FALSE | J24: =IF(I24,COUNTIF($I$2:I24,TRUE()),"")
A25: Atropine | B25: Anticholinergic | C25: 0.6 mg/ml, 1 mg/ml inj; 1% eye drops | D25: Glycopyrrolate (anaesthesia) | E25: Atropine (various) | F25: Atropine (various) | G25: A03BA01 | H25: Crash-cart item. | I25: =IF(Lookup!$B$3="",FALSE(),ISNUMBER(SEARCH(Lookup!$B$3,A25&" "&B25&" "&D25&" "&E25&" "&F25))) -> FALSE | J25: =IF(I25,COUNTIF($I$2:I25,TRUE()),"")
A26: Azithromycin | B26: Macrolide antibiotic | C26: 250/500 mg tab; 500 mg inj; 200 mg/5 ml susp | D26: Clarithromycin; Doxycycline (per indication) | E26: Azithral, Zithrox | F26: Zithromax, Azomax | G26: J01FA10 | I26: =IF(Lookup!$B$3="",FALSE(),ISNUMBER(SEARCH(Lookup!$B$3,A26&" "&B26&" "&D26&" "&E26&" "&F26))) -> FALSE | J26: =IF(I26,COUNTIF($I$2:I26,TRUE()),"")
A27: Bevacizumab | B27: VEGF monoclonal antibody | C27: 100/400 mg inj | D27: Bevacizumab biosimilars; Ranibizumab/aflibercept (ophthalmic use) | E27: Bevacirel, Abevmy (biosimilars) | F27: Avastin, Mvasi (biosimilar) | G27: L01FG01 | H27: Biosimilars. | I27: =IF(Lookup!$B$3="",FALSE(),ISNUMBER(SEARCH(Lookup!$B$3,A27&" "&B27&" "&D27&" "&E27&" "&F27))) -> FALSE | J27: =IF(I27,COUNTIF($I$2:I27,TRUE()),"")
A28: Bisoprolol | B28: Beta blocker | C28: 2.5/5/10 mg tab | D28: Metoprolol; Carvedilol; Nebivolol | E28: Concor, Bisoheart | F28: Concor | G28: C07AB07 | I28: =IF(Lookup!$B$3="",FALSE(),ISNUMBER(SEARCH(Lookup!$B$3,A28&" "&B28&" "&D28&" "&E28&" "&F28))) -> FALSE | J28: =IF(I28,COUNTIF($I$2:I28,TRUE()),"")
A29: Budesonide | B29: Inhaled corticosteroid | C29: 100/200/400 mcg inhaler; 0.5/1 mg nebule | D29: Fluticasone; Beclometasone; Mometasone | E29: Budecort, Pulmicort | F29: Pulmicort, Budecort | G29: R03BA02 | I29: =IF(Lookup!$B$3="",FALSE(),ISNUMBER(SEARCH(Lookup!$B$3,A29&" "&B29&" "&D29&" "&E29&" "&F29))) -> FALSE | J29: =IF(I29,COUNTIF($I$2:I29,TRUE()),"")
A30: Budesonide-formoterol | B30: ICS + LABA inhaler | C30: 160/4.5, 320/9 mcg | D30: Fluticasone-salmeterol; Fluticasone-vilanterol; Beclometasone-formoterol | E30: Foracort, Symbicort | F30: Symbicort, Vannair | G30: R03AK07 | I30: =IF(Lookup!$B$3="",FALSE(),ISNUMBER(SEARCH(Lookup!$B$3,A30&" "&B30&" "&D30&" "&E30&" "&F30))) -> FALSE | J30: =IF(I30,COUNTIF($I$2:I30,TRUE()),"")
A31: Bupivacaine | B31: Local anaesthetic | C31: 0.25%/0.5% inj; 0.5% heavy (spinal) | D31: Ropivacaine; Levobupivacaine | E31: Sensorcaine, Anawin | F31: Marcaine, Bupivacaine (various) | G31: N01BB01 | H31: Spinal 'heavy' presentation is the obstetric volume item. | I31: =IF(Lookup!$B$3="",FALSE(),ISNUMBER(SEARCH(Lookup!$B$3,A31&" "&B31&" "&D31&" "&E31&" "&F31))) -> FALSE | J31: =IF(I31,COUNTIF($I$2:I31,TRUE()),"")
A32: Calcium carbonate + vitamin D3 | B32: Mineral supplement | C32: 500 mg/250 IU tab | D32: Calcium citrate + D3 | E32: Shelcal, Calcimax | F32: Caltrate, Calcichew-D3 | G32: A12AX | I32: =IF(Lookup!$B$3="",FALSE(),ISNUMBER(SEARCH(Lookup!$B$3,A32&" "&B32&" "&D32&" "&E32&" "&F32))) -> FALSE | J32: =IF(I32,COUNTIF($I$2:I32,TRUE()),"")
A33: Capecitabine | B33: Antimetabolite chemotherapy (oral) | C33: 500 mg tab | D33: 5-Fluorouracil (IV) | E33: Capiibine, Xeloda | F33: Xeloda, Capecitabine (various) | G33: L01BC06 | I33: =IF(Lookup!$B$3="",FALSE(),ISNUMBER(SEARCH(Lookup!$B$3,A33&" "&B33&" "&D33&" "&E33&" "&F33))) -> FALSE | J33: =IF(I33,COUNTIF($I$2:I33,TRUE()),"")
A34: Carbamazepine | B34: Antiepileptic | C34: 200/400 mg tab (CR); syrup | D34: Oxcarbazepine; Levetiracetam; Valproate | E34: Tegretol, Zeptol | F34: Tegretol, Carbamazepine (various) | G34: N03AF01 | I34: =IF(Lookup!$B$3="",FALSE(),ISNUMBER(SEARCH(Lookup!$B$3,A34&" "&B34&" "&D34&" "&E34&" "&F34))) -> FALSE | J34: =IF(I34,COUNTIF($I$2:I34,TRUE()),"")
A35: Carbetocin | B35: Uterotonic (long-acting) | C35: 100 mcg/ml inj | D35: Oxytocin | E35: Duratocin, Carbetocin (various) | F35: Duratocin, Pabal | G35: H01BB03 | H35: Heat-stable formulation reduces cold-chain cost. | I35: =IF(Lookup!$B$3="",FALSE(),ISNUMBER(SEARCH(Lookup!$B$3,A35&" "&B35&" "&D35&" "&E35&" "&F35))) -> FALSE | J35: =IF(I35,COUNTIF($I$2:I35,TRUE()),"")
A36: Carbimazole | B36: Antithyroid | C36: 5/10/20 mg tab | D36: Methimazole; Propylthiouracil | E36: Neomercazole, Thyrocab | F36: Neomercazole | G36: H03BB01 | I36: =IF(Lookup!$B$3="",FALSE(),ISNUMBER(SEARCH(Lookup!$B$3,A36&" "&B36&" "&D36&" "&E36&" "&F36))) -> FALSE | J36: =IF(I36,COUNTIF($I$2:I36,TRUE()),"")
A37: Carboplatin | B37: Platinum chemotherapy | C37: 150/450 mg inj | D37: Cisplatin (protocol-specific) | E37: Carboplat, Kemocarb | F37: Carboplatin (various), Paraplatin | G37: L01XA02 | H37: Cytotoxic. | I37: =IF(Lookup!$B$3="",FALSE(),ISNUMBER(SEARCH(Lookup!$B$3,A37&" "&B37&" "&D37&" "&E37&" "&F37))) -> FALSE | J37: =IF(I37,COUNTIF($I$2:I37,TRUE()),"")
A38: Carboxymethylcellulose (eye) | B38: Lubricant eye drops | C38: 0.5%/1% drops | D38: Hypromellose; Polyethylene glycol/propylene glycol; Sodium hyaluronate | E38: Refresh Tears, Lubrex | F38: Refresh Tears, Optive, Systane | G38: S01XA20 | I38: =IF(Lookup!$B$3="",FALSE(),ISNUMBER(SEARCH(Lookup!$B$3,A38&" "&B38&" "&D38&" "&E38&" "&F38))) -> FALSE | J38: =IF(I38,COUNTIF($I$2:I38,TRUE()),"")
A39: Carvedilol | B39: Beta blocker (alpha/beta) | C39: 3.125/6.25/12.5/25 mg tab | D39: Bisoprolol; Metoprolol succinate | E39: Cardivas, Carca | F39: Dilatrend, Carvedil | G39: C07AG02 | I39: =IF(Lookup!$B$3="",FALSE(),ISNUMBER(SEARCH(Lookup!$B$3,A39&" "&B39&" "&D39&" "&E39&" "&F39))) -> FALSE | J39: =IF(I39,COUNTIF($I$2:I39,TRUE()),"")
A40: Caspofungin | B40: Echinocandin antifungal | C40: 50/70 mg inj | D40: Micafungin; Anidulafungin | E40: Cancidas, Caspof | F40: Cancidas | G40: J02AX04 | I40: =IF(Lookup!$B$3="",FALSE(),ISNUMBER(SEARCH(Lookup!$B$3,A40&" "&B40&" "&D40&" "&E40&" "&F40))) -> FALSE | J40: =IF(I40,COUNTIF($I$2:I40,TRUE()),"")
...
